2017-01-15 15:53:10,608 [Thread-21:4292] [django.request:170] [base:get_response] [WARNING]- Not Found: /js/table-my..js
2017-01-15 16:00:19,050 [Thread-8:4496] [django.request:256] [base:handle_uncaught_exception] [ERROR]- Internal Server Error: /kg/sellcard/fornt/cardcheck3/
Traceback (most recent call last):
  File "C:\Python34\lib\site-packages\django\core\handlers\base.py", line 132, in get_response
    response = wrapped_callback(request, *callback_args, **callback_kwargs)
  File "C:\Python34\lib\contextlib.py", line 30, in inner
    return func(*args, **kwds)
  File "D:/python/project/kggroup\sellcard\common\Method.py", line 149, in cardCheck_Change
    data['New_amount'] = float(data['New_amount'])
TypeError: 'NoneType' object is not subscriptable
2017-01-15 16:03:50,878 [Thread-7:7568] [django.request:256] [base:handle_uncaught_exception] [ERROR]- Internal Server Error: /kg/sellcard/fornt/cardchange/save
Traceback (most recent call last):
  File "C:\Python34\lib\site-packages\django\core\handlers\base.py", line 132, in get_response
    response = wrapped_callback(request, *callback_args, **callback_kwargs)
  File "C:\Python34\lib\contextlib.py", line 30, in inner
    return func(*args, **kwds)
  File "C:\Python34\lib\contextlib.py", line 30, in inner
    return func(*args, **kwds)
  File "D:/python/project/kggroup\sellcard\fornt\card\cardChange\card.py", line 203, in save
    return HttpResponse(json.dumps(res))
  File "C:\Python34\lib\json\__init__.py", line 230, in dumps
    return _default_encoder.encode(obj)
  File "C:\Python34\lib\json\encoder.py", line 192, in encode
    chunks = self.iterencode(o, _one_shot=True)
  File "C:\Python34\lib\json\encoder.py", line 250, in iterencode
    return _iterencode(o, 0)
  File "C:\Python34\lib\json\encoder.py", line 173, in default
    raise TypeError(repr(o) + " is not JSON serializable")
TypeError: MyError('ERP数据库卡状态更新失败',) is not JSON serializable
2017-01-15 16:06:00,103 [Thread-8:6900] [django.request:256] [base:handle_uncaught_exception] [ERROR]- Internal Server Error: /kg/sellcard/fornt/cardchange/save
Traceback (most recent call last):
  File "C:\Python34\lib\site-packages\django\core\handlers\base.py", line 132, in get_response
    response = wrapped_callback(request, *callback_args, **callback_kwargs)
  File "C:\Python34\lib\contextlib.py", line 30, in inner
    return func(*args, **kwds)
  File "C:\Python34\lib\contextlib.py", line 30, in inner
    return func(*args, **kwds)
  File "D:/python/project/kggroup\sellcard\fornt\card\cardChange\card.py", line 203, in save
    return HttpResponse(json.dumps(res))
  File "C:\Python34\lib\json\__init__.py", line 230, in dumps
    return _default_encoder.encode(obj)
  File "C:\Python34\lib\json\encoder.py", line 192, in encode
    chunks = self.iterencode(o, _one_shot=True)
  File "C:\Python34\lib\json\encoder.py", line 250, in iterencode
    return _iterencode(o, 0)
  File "C:\Python34\lib\json\encoder.py", line 173, in default
    raise TypeError(repr(o) + " is not JSON serializable")
TypeError: MyError('ERP数据库卡状态更新失败',) is not JSON serializable
2017-01-15 16:08:51,679 [Thread-9:10048] [django.request:256] [base:handle_uncaught_exception] [ERROR]- Internal Server Error: /kg/sellcard/fornt/cardchange/save
Traceback (most recent call last):
  File "C:\Python34\lib\site-packages\django\core\handlers\base.py", line 132, in get_response
    response = wrapped_callback(request, *callback_args, **callback_kwargs)
  File "C:\Python34\lib\contextlib.py", line 30, in inner
    return func(*args, **kwds)
  File "C:\Python34\lib\contextlib.py", line 30, in inner
    return func(*args, **kwds)
  File "D:/python/project/kggroup\sellcard\fornt\card\cardChange\card.py", line 203, in save
    return HttpResponse(json.dumps(res))
  File "C:\Python34\lib\json\__init__.py", line 230, in dumps
    return _default_encoder.encode(obj)
  File "C:\Python34\lib\json\encoder.py", line 192, in encode
    chunks = self.iterencode(o, _one_shot=True)
  File "C:\Python34\lib\json\encoder.py", line 250, in iterencode
    return _iterencode(o, 0)
  File "C:\Python34\lib\json\encoder.py", line 173, in default
    raise TypeError(repr(o) + " is not JSON serializable")
TypeError: MyError('ERP数据库卡状态更新失败',) is not JSON serializable
2017-01-15 16:23:14,615 [Thread-7:404] [django.request:256] [base:handle_uncaught_exception] [ERROR]- Internal Server Error: /kg/sellcard/fornt/cardchange/save
Traceback (most recent call last):
  File "C:\Python34\lib\site-packages\django\core\handlers\base.py", line 132, in get_response
    response = wrapped_callback(request, *callback_args, **callback_kwargs)
  File "C:\Python34\lib\contextlib.py", line 30, in inner
    return func(*args, **kwds)
  File "C:\Python34\lib\contextlib.py", line 30, in inner
    return func(*args, **kwds)
  File "D:/python/project/kggroup\sellcard\fornt\card\cardChange\card.py", line 201, in save
    return HttpResponse(json.dumps(res))
  File "C:\Python34\lib\json\__init__.py", line 230, in dumps
    return _default_encoder.encode(obj)
  File "C:\Python34\lib\json\encoder.py", line 192, in encode
    chunks = self.iterencode(o, _one_shot=True)
  File "C:\Python34\lib\json\encoder.py", line 250, in iterencode
    return _iterencode(o, 0)
  File "C:\Python34\lib\json\encoder.py", line 173, in default
    raise TypeError(repr(o) + " is not JSON serializable")
TypeError: MyError('ERP数据库卡状态更新失败',) is not JSON serializable
2017-01-15 16:24:17,804 [Thread-7:8984] [django.request:256] [base:handle_uncaught_exception] [ERROR]- Internal Server Error: /kg/sellcard/fornt/cardchange/save
Traceback (most recent call last):
  File "C:\Python34\lib\site-packages\django\core\handlers\base.py", line 132, in get_response
    response = wrapped_callback(request, *callback_args, **callback_kwargs)
  File "C:\Python34\lib\contextlib.py", line 30, in inner
    return func(*args, **kwds)
  File "C:\Python34\lib\contextlib.py", line 30, in inner
    return func(*args, **kwds)
  File "D:/python/project/kggroup\sellcard\fornt\card\cardChange\card.py", line 201, in save
    return HttpResponse(json.dumps(res))
  File "C:\Python34\lib\json\__init__.py", line 230, in dumps
    return _default_encoder.encode(obj)
  File "C:\Python34\lib\json\encoder.py", line 192, in encode
    chunks = self.iterencode(o, _one_shot=True)
  File "C:\Python34\lib\json\encoder.py", line 250, in iterencode
    return _iterencode(o, 0)
  File "C:\Python34\lib\json\encoder.py", line 173, in default
    raise TypeError(repr(o) + " is not JSON serializable")
TypeError: MyError('ERP数据库卡状态更新失败',) is not JSON serializable
2017-01-15 16:25:59,115 [Thread-27:7484] [django.request:256] [base:handle_uncaught_exception] [ERROR]- Internal Server Error: /kg/sellcard/fornt/cardcheck3/
Traceback (most recent call last):
  File "pymssql.pyx", line 445, in pymssql.Cursor.execute (pymssql.c:6810)
  File "_mssql.pyx", line 998, in _mssql.MSSQLConnection.execute_query (_mssql.c:10765)
  File "_mssql.pyx", line 1029, in _mssql.MSSQLConnection.execute_query (_mssql.c:10639)
  File "_mssql.pyx", line 1162, in _mssql.MSSQLConnection.format_and_run_query (_mssql.c:11894)
  File "_mssql.pyx", line 1568, in _mssql.check_cancel_and_raise (_mssql.c:15788)
  File "_mssql.pyx", line 1612, in _mssql.maybe_raise_MSSQLDatabaseException (_mssql.c:16426)
_mssql.MSSQLDatabaseException: (102, b"Incorrect syntax near 'sn'.DB-Lib error message 20018, severity 15:\nGeneral SQL Server error: Check messages from the SQL Server\n")

During handling of the above exception, another exception occurred:

Traceback (most recent call last):
  File "C:\Python34\lib\site-packages\django\core\handlers\base.py", line 132, in get_response
    response = wrapped_callback(request, *callback_args, **callback_kwargs)
  File "C:\Python34\lib\contextlib.py", line 30, in inner
    return func(*args, **kwds)
  File "D:/python/project/kggroup\sellcard\common\Method.py", line 147, in cardCheck_Change
    cursor.execute(sql)
  File "pymssql.pyx", line 462, in pymssql.Cursor.execute (pymssql.c:7136)
pymssql.ProgrammingError: (102, b"Incorrect syntax near 'sn'.DB-Lib error message 20018, severity 15:\nGeneral SQL Server error: Check messages from the SQL Server\n")
2017-01-15 16:43:44,716 [Thread-12:9424] [django.request:170] [base:get_response] [WARNING]- Not Found: /kg/sellcard/report/card/shopsale/order/favicon.ico
2017-01-15 16:43:44,840 [Thread-13:8084] [django.request:170] [base:get_response] [WARNING]- Not Found: /kg/sellcard/report/card/shopsale/order/favicon.ico
2017-01-16 08:45:41,450 [Thread-1:696] [django.request:170] [base:get_response] [WARNING]- Not Found: /
2017-01-16 08:45:44,292 [Thread-3:5004] [django.request:170] [base:get_response] [WARNING]- Not Found: /favicon.ico
2017-01-16 08:45:55,398 [Thread-7:10304] [django.request:170] [base:get_response] [WARNING]- Not Found: /kg/sellcard/updatepwd/favicon.ico
2017-01-16 08:49:25,621 [Thread-29:10352] [django.request:170] [base:get_response] [WARNING]- Not Found: /kg/sellcard/index/favicon.ico
2017-01-16 08:50:00,610 [Thread-32:8312] [django.request:170] [base:get_response] [WARNING]- Not Found: /kg/sellcard/fornt/cardsale/favicon.ico
2017-01-16 08:50:00,888 [Thread-33:3936] [django.request:170] [base:get_response] [WARNING]- Not Found: /kg/sellcard/fornt/cardsale/favicon.ico
2017-01-16 08:50:50,500 [Thread-37:2780] [django.request:170] [base:get_response] [WARNING]- Not Found: /kg/sellcard/fornt/cardsale/orderInfo/favicon.ico
2017-01-16 08:50:50,554 [Thread-38:10312] [django.request:170] [base:get_response] [WARNING]- Not Found: /kg/sellcard/fornt/cardsale/orderInfo/favicon.ico
2017-01-16 10:10:39,025 [Thread-138:2748] [django.request:170] [base:get_response] [WARNING]- Not Found: /js/jquery.min.map
2017-01-16 10:12:34,611 [Thread-158:10620] [django.request:170] [base:get_response] [WARNING]- Not Found: /js/jquery.min.map
2017-01-17 21:28:08,263 [Thread-11:17132] [django.request:170] [base:get_response] [WARNING]- Not Found: /js/table-my..js
2017-01-17 21:28:08,658 [Thread-20:11852] [django.request:170] [base:get_response] [WARNING]- Not Found: /favicon.ico
2017-01-17 21:28:22,633 [Thread-31:12000] [django.request:170] [base:get_response] [WARNING]- Not Found: /favicon.ico
2017-01-17 21:28:47,106 [Thread-33:11704] [django.request:256] [base:handle_uncaught_exception] [ERROR]- Internal Server Error: /kg/sellcard/report/voucher/stock/
Traceback (most recent call last):
  File "C:\Users\QX\AppData\Local\Programs\Python\Python35-32\lib\site-packages\django\db\backends\utils.py", line 64, in execute
    return self.cursor.execute(sql, params)
  File "C:\Users\QX\AppData\Local\Programs\Python\Python35-32\lib\site-packages\django\db\backends\mysql\base.py", line 124, in execute
    return self.cursor.execute(query, args)
  File "C:\Users\QX\AppData\Local\Programs\Python\Python35-32\lib\site-packages\pymysql\cursors.py", line 166, in execute
    result = self._query(query)
  File "C:\Users\QX\AppData\Local\Programs\Python\Python35-32\lib\site-packages\pymysql\cursors.py", line 322, in _query
    conn.query(q)
  File "C:\Users\QX\AppData\Local\Programs\Python\Python35-32\lib\site-packages\pymysql\connections.py", line 835, in query
    self._affected_rows = self._read_query_result(unbuffered=unbuffered)
  File "C:\Users\QX\AppData\Local\Programs\Python\Python35-32\lib\site-packages\pymysql\connections.py", line 1019, in _read_query_result
    result.read()
  File "C:\Users\QX\AppData\Local\Programs\Python\Python35-32\lib\site-packages\pymysql\connections.py", line 1302, in read
    first_packet = self.connection._read_packet()
  File "C:\Users\QX\AppData\Local\Programs\Python\Python35-32\lib\site-packages\pymysql\connections.py", line 981, in _read_packet
    packet.check_error()
  File "C:\Users\QX\AppData\Local\Programs\Python\Python35-32\lib\site-packages\pymysql\connections.py", line 393, in check_error
    err.raise_mysql_exception(self._data)
  File "C:\Users\QX\AppData\Local\Programs\Python\Python35-32\lib\site-packages\pymysql\err.py", line 107, in raise_mysql_exception
    raise errorclass(errno, errval)
pymysql.err.ProgrammingError: (1146, "Table 'kggroup.kf_jobs_coupon_new' doesn't exist")

The above exception was the direct cause of the following exception:

Traceback (most recent call last):
  File "C:\Users\QX\AppData\Local\Programs\Python\Python35-32\lib\site-packages\django\core\handlers\base.py", line 132, in get_response
    response = wrapped_callback(request, *callback_args, **callback_kwargs)
  File "C:\Users\QX\AppData\Local\Programs\Python\Python35-32\lib\contextlib.py", line 30, in inner
    return func(*args, **kwds)
  File "E:\PythonWorkSpace\kggroup\sellcard\report\voucher\stock.py", line 64, in index
    for item in List:
  File "C:\Users\QX\AppData\Local\Programs\Python\Python35-32\lib\site-packages\django\db\models\query.py", line 162, in __iter__
    self._fetch_all()
  File "C:\Users\QX\AppData\Local\Programs\Python\Python35-32\lib\site-packages\django\db\models\query.py", line 965, in _fetch_all
    self._result_cache = list(self.iterator())
  File "C:\Users\QX\AppData\Local\Programs\Python\Python35-32\lib\site-packages\django\db\models\query.py", line 1085, in iterator
    for row in self.query.get_compiler(self.db).results_iter():
  File "C:\Users\QX\AppData\Local\Programs\Python\Python35-32\lib\site-packages\django\db\models\sql\compiler.py", line 794, in results_iter
    results = self.execute_sql(MULTI)
  File "C:\Users\QX\AppData\Local\Programs\Python\Python35-32\lib\site-packages\django\db\models\sql\compiler.py", line 840, in execute_sql
    cursor.execute(sql, params)
  File "C:\Users\QX\AppData\Local\Programs\Python\Python35-32\lib\site-packages\django\db\backends\utils.py", line 64, in execute
    return self.cursor.execute(sql, params)
  File "C:\Users\QX\AppData\Local\Programs\Python\Python35-32\lib\site-packages\django\db\utils.py", line 97, in __exit__
    six.reraise(dj_exc_type, dj_exc_value, traceback)
  File "C:\Users\QX\AppData\Local\Programs\Python\Python35-32\lib\site-packages\django\utils\six.py", line 658, in reraise
    raise value.with_traceback(tb)
  File "C:\Users\QX\AppData\Local\Programs\Python\Python35-32\lib\site-packages\django\db\backends\utils.py", line 64, in execute
    return self.cursor.execute(sql, params)
  File "C:\Users\QX\AppData\Local\Programs\Python\Python35-32\lib\site-packages\django\db\backends\mysql\base.py", line 124, in execute
    return self.cursor.execute(query, args)
  File "C:\Users\QX\AppData\Local\Programs\Python\Python35-32\lib\site-packages\pymysql\cursors.py", line 166, in execute
    result = self._query(query)
  File "C:\Users\QX\AppData\Local\Programs\Python\Python35-32\lib\site-packages\pymysql\cursors.py", line 322, in _query
    conn.query(q)
  File "C:\Users\QX\AppData\Local\Programs\Python\Python35-32\lib\site-packages\pymysql\connections.py", line 835, in query
    self._affected_rows = self._read_query_result(unbuffered=unbuffered)
  File "C:\Users\QX\AppData\Local\Programs\Python\Python35-32\lib\site-packages\pymysql\connections.py", line 1019, in _read_query_result
    result.read()
  File "C:\Users\QX\AppData\Local\Programs\Python\Python35-32\lib\site-packages\pymysql\connections.py", line 1302, in read
    first_packet = self.connection._read_packet()
  File "C:\Users\QX\AppData\Local\Programs\Python\Python35-32\lib\site-packages\pymysql\connections.py", line 981, in _read_packet
    packet.check_error()
  File "C:\Users\QX\AppData\Local\Programs\Python\Python35-32\lib\site-packages\pymysql\connections.py", line 393, in check_error
    err.raise_mysql_exception(self._data)
  File "C:\Users\QX\AppData\Local\Programs\Python\Python35-32\lib\site-packages\pymysql\err.py", line 107, in raise_mysql_exception
    raise errorclass(errno, errval)
django.db.utils.ProgrammingError: (1146, "Table 'kggroup.kf_jobs_coupon_new' doesn't exist")
2017-01-17 21:29:08,671 [Thread-49:14600] [django.request:256] [base:handle_uncaught_exception] [ERROR]- Internal Server Error: /kg/sellcard/report/voucher/stock/
Traceback (most recent call last):
  File "C:\Users\QX\AppData\Local\Programs\Python\Python35-32\lib\site-packages\django\db\backends\utils.py", line 64, in execute
    return self.cursor.execute(sql, params)
  File "C:\Users\QX\AppData\Local\Programs\Python\Python35-32\lib\site-packages\django\db\backends\mysql\base.py", line 124, in execute
    return self.cursor.execute(query, args)
  File "C:\Users\QX\AppData\Local\Programs\Python\Python35-32\lib\site-packages\pymysql\cursors.py", line 166, in execute
    result = self._query(query)
  File "C:\Users\QX\AppData\Local\Programs\Python\Python35-32\lib\site-packages\pymysql\cursors.py", line 322, in _query
    conn.query(q)
  File "C:\Users\QX\AppData\Local\Programs\Python\Python35-32\lib\site-packages\pymysql\connections.py", line 835, in query
    self._affected_rows = self._read_query_result(unbuffered=unbuffered)
  File "C:\Users\QX\AppData\Local\Programs\Python\Python35-32\lib\site-packages\pymysql\connections.py", line 1019, in _read_query_result
    result.read()
  File "C:\Users\QX\AppData\Local\Programs\Python\Python35-32\lib\site-packages\pymysql\connections.py", line 1302, in read
    first_packet = self.connection._read_packet()
  File "C:\Users\QX\AppData\Local\Programs\Python\Python35-32\lib\site-packages\pymysql\connections.py", line 981, in _read_packet
    packet.check_error()
  File "C:\Users\QX\AppData\Local\Programs\Python\Python35-32\lib\site-packages\pymysql\connections.py", line 393, in check_error
    err.raise_mysql_exception(self._data)
  File "C:\Users\QX\AppData\Local\Programs\Python\Python35-32\lib\site-packages\pymysql\err.py", line 107, in raise_mysql_exception
    raise errorclass(errno, errval)
pymysql.err.ProgrammingError: (1146, "Table 'kggroup.kf_jobs_coupon_new' doesn't exist")

The above exception was the direct cause of the following exception:

Traceback (most recent call last):
  File "C:\Users\QX\AppData\Local\Programs\Python\Python35-32\lib\site-packages\django\core\handlers\base.py", line 132, in get_response
    response = wrapped_callback(request, *callback_args, **callback_kwargs)
  File "C:\Users\QX\AppData\Local\Programs\Python\Python35-32\lib\contextlib.py", line 30, in inner
    return func(*args, **kwds)
  File "E:\PythonWorkSpace\kggroup\sellcard\report\voucher\stock.py", line 64, in index
    for item in List:
  File "C:\Users\QX\AppData\Local\Programs\Python\Python35-32\lib\site-packages\django\db\models\query.py", line 162, in __iter__
    self._fetch_all()
  File "C:\Users\QX\AppData\Local\Programs\Python\Python35-32\lib\site-packages\django\db\models\query.py", line 965, in _fetch_all
    self._result_cache = list(self.iterator())
  File "C:\Users\QX\AppData\Local\Programs\Python\Python35-32\lib\site-packages\django\db\models\query.py", line 1085, in iterator
    for row in self.query.get_compiler(self.db).results_iter():
  File "C:\Users\QX\AppData\Local\Programs\Python\Python35-32\lib\site-packages\django\db\models\sql\compiler.py", line 794, in results_iter
    results = self.execute_sql(MULTI)
  File "C:\Users\QX\AppData\Local\Programs\Python\Python35-32\lib\site-packages\django\db\models\sql\compiler.py", line 840, in execute_sql
    cursor.execute(sql, params)
  File "C:\Users\QX\AppData\Local\Programs\Python\Python35-32\lib\site-packages\django\db\backends\utils.py", line 64, in execute
    return self.cursor.execute(sql, params)
  File "C:\Users\QX\AppData\Local\Programs\Python\Python35-32\lib\site-packages\django\db\utils.py", line 97, in __exit__
    six.reraise(dj_exc_type, dj_exc_value, traceback)
  File "C:\Users\QX\AppData\Local\Programs\Python\Python35-32\lib\site-packages\django\utils\six.py", line 658, in reraise
    raise value.with_traceback(tb)
  File "C:\Users\QX\AppData\Local\Programs\Python\Python35-32\lib\site-packages\django\db\backends\utils.py", line 64, in execute
    return self.cursor.execute(sql, params)
  File "C:\Users\QX\AppData\Local\Programs\Python\Python35-32\lib\site-packages\django\db\backends\mysql\base.py", line 124, in execute
    return self.cursor.execute(query, args)
  File "C:\Users\QX\AppData\Local\Programs\Python\Python35-32\lib\site-packages\pymysql\cursors.py", line 166, in execute
    result = self._query(query)
  File "C:\Users\QX\AppData\Local\Programs\Python\Python35-32\lib\site-packages\pymysql\cursors.py", line 322, in _query
    conn.query(q)
  File "C:\Users\QX\AppData\Local\Programs\Python\Python35-32\lib\site-packages\pymysql\connections.py", line 835, in query
    self._affected_rows = self._read_query_result(unbuffered=unbuffered)
  File "C:\Users\QX\AppData\Local\Programs\Python\Python35-32\lib\site-packages\pymysql\connections.py", line 1019, in _read_query_result
    result.read()
  File "C:\Users\QX\AppData\Local\Programs\Python\Python35-32\lib\site-packages\pymysql\connections.py", line 1302, in read
    first_packet = self.connection._read_packet()
  File "C:\Users\QX\AppData\Local\Programs\Python\Python35-32\lib\site-packages\pymysql\connections.py", line 981, in _read_packet
    packet.check_error()
  File "C:\Users\QX\AppData\Local\Programs\Python\Python35-32\lib\site-packages\pymysql\connections.py", line 393, in check_error
    err.raise_mysql_exception(self._data)
  File "C:\Users\QX\AppData\Local\Programs\Python\Python35-32\lib\site-packages\pymysql\err.py", line 107, in raise_mysql_exception
    raise errorclass(errno, errval)
django.db.utils.ProgrammingError: (1146, "Table 'kggroup.kf_jobs_coupon_new' doesn't exist")
2017-01-17 21:29:16,517 [Thread-55:14240] [django.request:256] [base:handle_uncaught_exception] [ERROR]- Internal Server Error: /kg/sellcard/fornt/voucher/issue/
Traceback (most recent call last):
  File "C:\Users\QX\AppData\Local\Programs\Python\Python35-32\lib\site-packages\django\db\backends\utils.py", line 64, in execute
    return self.cursor.execute(sql, params)
  File "C:\Users\QX\AppData\Local\Programs\Python\Python35-32\lib\site-packages\django\db\backends\mysql\base.py", line 124, in execute
    return self.cursor.execute(query, args)
  File "C:\Users\QX\AppData\Local\Programs\Python\Python35-32\lib\site-packages\pymysql\cursors.py", line 166, in execute
    result = self._query(query)
  File "C:\Users\QX\AppData\Local\Programs\Python\Python35-32\lib\site-packages\pymysql\cursors.py", line 322, in _query
    conn.query(q)
  File "C:\Users\QX\AppData\Local\Programs\Python\Python35-32\lib\site-packages\pymysql\connections.py", line 835, in query
    self._affected_rows = self._read_query_result(unbuffered=unbuffered)
  File "C:\Users\QX\AppData\Local\Programs\Python\Python35-32\lib\site-packages\pymysql\connections.py", line 1019, in _read_query_result
    result.read()
  File "C:\Users\QX\AppData\Local\Programs\Python\Python35-32\lib\site-packages\pymysql\connections.py", line 1302, in read
    first_packet = self.connection._read_packet()
  File "C:\Users\QX\AppData\Local\Programs\Python\Python35-32\lib\site-packages\pymysql\connections.py", line 981, in _read_packet
    packet.check_error()
  File "C:\Users\QX\AppData\Local\Programs\Python\Python35-32\lib\site-packages\pymysql\connections.py", line 393, in check_error
    err.raise_mysql_exception(self._data)
  File "C:\Users\QX\AppData\Local\Programs\Python\Python35-32\lib\site-packages\pymysql\err.py", line 107, in raise_mysql_exception
    raise errorclass(errno, errval)
pymysql.err.ProgrammingError: (1146, "Table 'kggroup.kf_jobs_coupon_new' doesn't exist")

The above exception was the direct cause of the following exception:

Traceback (most recent call last):
  File "C:\Users\QX\AppData\Local\Programs\Python\Python35-32\lib\site-packages\django\core\handlers\base.py", line 132, in get_response
    response = wrapped_callback(request, *callback_args, **callback_kwargs)
  File "C:\Users\QX\AppData\Local\Programs\Python\Python35-32\lib\contextlib.py", line 30, in inner
    return func(*args, **kwds)
  File "C:\Users\QX\AppData\Local\Programs\Python\Python35-32\lib\contextlib.py", line 30, in inner
    return func(*args, **kwds)
  File "E:\PythonWorkSpace\kggroup\sellcard\fornt\voucher\issue.py", line 70, in index
    return render(request, 'voucher/issue/List.html', locals())
  File "C:\Users\QX\AppData\Local\Programs\Python\Python35-32\lib\site-packages\django\shortcuts.py", line 67, in render
    template_name, context, request=request, using=using)
  File "C:\Users\QX\AppData\Local\Programs\Python\Python35-32\lib\site-packages\django\template\loader.py", line 99, in render_to_string
    return template.render(context, request)
  File "C:\Users\QX\AppData\Local\Programs\Python\Python35-32\lib\site-packages\django\template\backends\django.py", line 74, in render
    return self.template.render(context)
  File "C:\Users\QX\AppData\Local\Programs\Python\Python35-32\lib\site-packages\django\template\base.py", line 209, in render
    return self._render(context)
  File "C:\Users\QX\AppData\Local\Programs\Python\Python35-32\lib\site-packages\django\template\base.py", line 201, in _render
    return self.nodelist.render(context)
  File "C:\Users\QX\AppData\Local\Programs\Python\Python35-32\lib\site-packages\django\template\base.py", line 903, in render
    bit = self.render_node(node, context)
  File "C:\Users\QX\AppData\Local\Programs\Python\Python35-32\lib\site-packages\django\template\base.py", line 917, in render_node
    return node.render(context)
  File "C:\Users\QX\AppData\Local\Programs\Python\Python35-32\lib\site-packages\django\template\defaulttags.py", line 162, in render
    len_values = len(values)
  File "C:\Users\QX\AppData\Local\Programs\Python\Python35-32\lib\site-packages\django\db\models\query.py", line 144, in __len__
    self._fetch_all()
  File "C:\Users\QX\AppData\Local\Programs\Python\Python35-32\lib\site-packages\django\db\models\query.py", line 965, in _fetch_all
    self._result_cache = list(self.iterator())
  File "C:\Users\QX\AppData\Local\Programs\Python\Python35-32\lib\site-packages\django\db\models\query.py", line 1085, in iterator
    for row in self.query.get_compiler(self.db).results_iter():
  File "C:\Users\QX\AppData\Local\Programs\Python\Python35-32\lib\site-packages\django\db\models\sql\compiler.py", line 794, in results_iter
    results = self.execute_sql(MULTI)
  File "C:\Users\QX\AppData\Local\Programs\Python\Python35-32\lib\site-packages\django\db\models\sql\compiler.py", line 840, in execute_sql
    cursor.execute(sql, params)
  File "C:\Users\QX\AppData\Local\Programs\Python\Python35-32\lib\site-packages\django\db\backends\utils.py", line 64, in execute
    return self.cursor.execute(sql, params)
  File "C:\Users\QX\AppData\Local\Programs\Python\Python35-32\lib\site-packages\django\db\utils.py", line 97, in __exit__
    six.reraise(dj_exc_type, dj_exc_value, traceback)
  File "C:\Users\QX\AppData\Local\Programs\Python\Python35-32\lib\site-packages\django\utils\six.py", line 658, in reraise
    raise value.with_traceback(tb)
  File "C:\Users\QX\AppData\Local\Programs\Python\Python35-32\lib\site-packages\django\db\backends\utils.py", line 64, in execute
    return self.cursor.execute(sql, params)
  File "C:\Users\QX\AppData\Local\Programs\Python\Python35-32\lib\site-packages\django\db\backends\mysql\base.py", line 124, in execute
    return self.cursor.execute(query, args)
  File "C:\Users\QX\AppData\Local\Programs\Python\Python35-32\lib\site-packages\pymysql\cursors.py", line 166, in execute
    result = self._query(query)
  File "C:\Users\QX\AppData\Local\Programs\Python\Python35-32\lib\site-packages\pymysql\cursors.py", line 322, in _query
    conn.query(q)
  File "C:\Users\QX\AppData\Local\Programs\Python\Python35-32\lib\site-packages\pymysql\connections.py", line 835, in query
    self._affected_rows = self._read_query_result(unbuffered=unbuffered)
  File "C:\Users\QX\AppData\Local\Programs\Python\Python35-32\lib\site-packages\pymysql\connections.py", line 1019, in _read_query_result
    result.read()
  File "C:\Users\QX\AppData\Local\Programs\Python\Python35-32\lib\site-packages\pymysql\connections.py", line 1302, in read
    first_packet = self.connection._read_packet()
  File "C:\Users\QX\AppData\Local\Programs\Python\Python35-32\lib\site-packages\pymysql\connections.py", line 981, in _read_packet
    packet.check_error()
  File "C:\Users\QX\AppData\Local\Programs\Python\Python35-32\lib\site-packages\pymysql\connections.py", line 393, in check_error
    err.raise_mysql_exception(self._data)
  File "C:\Users\QX\AppData\Local\Programs\Python\Python35-32\lib\site-packages\pymysql\err.py", line 107, in raise_mysql_exception
    raise errorclass(errno, errval)
django.db.utils.ProgrammingError: (1146, "Table 'kggroup.kf_jobs_coupon_new' doesn't exist")
2017-01-17 21:31:23,171 [Thread-31:21296] [django.request:256] [base:handle_uncaught_exception] [ERROR]- Internal Server Error: /kg/sellcard/fornt/voucher/issue/
Traceback (most recent call last):
  File "C:\Users\QX\AppData\Local\Programs\Python\Python35-32\lib\site-packages\django\db\backends\utils.py", line 64, in execute
    return self.cursor.execute(sql, params)
  File "C:\Users\QX\AppData\Local\Programs\Python\Python35-32\lib\site-packages\django\db\backends\mysql\base.py", line 124, in execute
    return self.cursor.execute(query, args)
  File "C:\Users\QX\AppData\Local\Programs\Python\Python35-32\lib\site-packages\pymysql\cursors.py", line 166, in execute
    result = self._query(query)
  File "C:\Users\QX\AppData\Local\Programs\Python\Python35-32\lib\site-packages\pymysql\cursors.py", line 322, in _query
    conn.query(q)
  File "C:\Users\QX\AppData\Local\Programs\Python\Python35-32\lib\site-packages\pymysql\connections.py", line 835, in query
    self._affected_rows = self._read_query_result(unbuffered=unbuffered)
  File "C:\Users\QX\AppData\Local\Programs\Python\Python35-32\lib\site-packages\pymysql\connections.py", line 1019, in _read_query_result
    result.read()
  File "C:\Users\QX\AppData\Local\Programs\Python\Python35-32\lib\site-packages\pymysql\connections.py", line 1302, in read
    first_packet = self.connection._read_packet()
  File "C:\Users\QX\AppData\Local\Programs\Python\Python35-32\lib\site-packages\pymysql\connections.py", line 981, in _read_packet
    packet.check_error()
  File "C:\Users\QX\AppData\Local\Programs\Python\Python35-32\lib\site-packages\pymysql\connections.py", line 393, in check_error
    err.raise_mysql_exception(self._data)
  File "C:\Users\QX\AppData\Local\Programs\Python\Python35-32\lib\site-packages\pymysql\err.py", line 107, in raise_mysql_exception
    raise errorclass(errno, errval)
pymysql.err.ProgrammingError: (1146, "Table 'kggroup.kf_jobs_coupon_new' doesn't exist")

The above exception was the direct cause of the following exception:

Traceback (most recent call last):
  File "C:\Users\QX\AppData\Local\Programs\Python\Python35-32\lib\site-packages\django\core\handlers\base.py", line 132, in get_response
    response = wrapped_callback(request, *callback_args, **callback_kwargs)
  File "C:\Users\QX\AppData\Local\Programs\Python\Python35-32\lib\contextlib.py", line 30, in inner
    return func(*args, **kwds)
  File "C:\Users\QX\AppData\Local\Programs\Python\Python35-32\lib\contextlib.py", line 30, in inner
    return func(*args, **kwds)
  File "E:/PythonWorkSpace/kggroup\sellcard\fornt\voucher\issue.py", line 70, in index
    return render(request, 'voucher/issue/List.html', locals())
  File "C:\Users\QX\AppData\Local\Programs\Python\Python35-32\lib\site-packages\django\shortcuts.py", line 67, in render
    template_name, context, request=request, using=using)
  File "C:\Users\QX\AppData\Local\Programs\Python\Python35-32\lib\site-packages\django\template\loader.py", line 99, in render_to_string
    return template.render(context, request)
  File "C:\Users\QX\AppData\Local\Programs\Python\Python35-32\lib\site-packages\django\template\backends\django.py", line 74, in render
    return self.template.render(context)
  File "C:\Users\QX\AppData\Local\Programs\Python\Python35-32\lib\site-packages\django\template\base.py", line 209, in render
    return self._render(context)
  File "C:\Users\QX\AppData\Local\Programs\Python\Python35-32\lib\site-packages\django\template\base.py", line 201, in _render
    return self.nodelist.render(context)
  File "C:\Users\QX\AppData\Local\Programs\Python\Python35-32\lib\site-packages\django\template\base.py", line 903, in render
    bit = self.render_node(node, context)
  File "C:\Users\QX\AppData\Local\Programs\Python\Python35-32\lib\site-packages\django\template\base.py", line 917, in render_node
    return node.render(context)
  File "C:\Users\QX\AppData\Local\Programs\Python\Python35-32\lib\site-packages\django\template\defaulttags.py", line 162, in render
    len_values = len(values)
  File "C:\Users\QX\AppData\Local\Programs\Python\Python35-32\lib\site-packages\django\db\models\query.py", line 144, in __len__
    self._fetch_all()
  File "C:\Users\QX\AppData\Local\Programs\Python\Python35-32\lib\site-packages\django\db\models\query.py", line 965, in _fetch_all
    self._result_cache = list(self.iterator())
  File "C:\Users\QX\AppData\Local\Programs\Python\Python35-32\lib\site-packages\django\db\models\query.py", line 1085, in iterator
    for row in self.query.get_compiler(self.db).results_iter():
  File "C:\Users\QX\AppData\Local\Programs\Python\Python35-32\lib\site-packages\django\db\models\sql\compiler.py", line 794, in results_iter
    results = self.execute_sql(MULTI)
  File "C:\Users\QX\AppData\Local\Programs\Python\Python35-32\lib\site-packages\django\db\models\sql\compiler.py", line 840, in execute_sql
    cursor.execute(sql, params)
  File "C:\Users\QX\AppData\Local\Programs\Python\Python35-32\lib\site-packages\django\db\backends\utils.py", line 64, in execute
    return self.cursor.execute(sql, params)
  File "C:\Users\QX\AppData\Local\Programs\Python\Python35-32\lib\site-packages\django\db\utils.py", line 97, in __exit__
    six.reraise(dj_exc_type, dj_exc_value, traceback)
  File "C:\Users\QX\AppData\Local\Programs\Python\Python35-32\lib\site-packages\django\utils\six.py", line 658, in reraise
    raise value.with_traceback(tb)
  File "C:\Users\QX\AppData\Local\Programs\Python\Python35-32\lib\site-packages\django\db\backends\utils.py", line 64, in execute
    return self.cursor.execute(sql, params)
  File "C:\Users\QX\AppData\Local\Programs\Python\Python35-32\lib\site-packages\django\db\backends\mysql\base.py", line 124, in execute
    return self.cursor.execute(query, args)
  File "C:\Users\QX\AppData\Local\Programs\Python\Python35-32\lib\site-packages\pymysql\cursors.py", line 166, in execute
    result = self._query(query)
  File "C:\Users\QX\AppData\Local\Programs\Python\Python35-32\lib\site-packages\pymysql\cursors.py", line 322, in _query
    conn.query(q)
  File "C:\Users\QX\AppData\Local\Programs\Python\Python35-32\lib\site-packages\pymysql\connections.py", line 835, in query
    self._affected_rows = self._read_query_result(unbuffered=unbuffered)
  File "C:\Users\QX\AppData\Local\Programs\Python\Python35-32\lib\site-packages\pymysql\connections.py", line 1019, in _read_query_result
    result.read()
  File "C:\Users\QX\AppData\Local\Programs\Python\Python35-32\lib\site-packages\pymysql\connections.py", line 1302, in read
    first_packet = self.connection._read_packet()
  File "C:\Users\QX\AppData\Local\Programs\Python\Python35-32\lib\site-packages\pymysql\connections.py", line 981, in _read_packet
    packet.check_error()
  File "C:\Users\QX\AppData\Local\Programs\Python\Python35-32\lib\site-packages\pymysql\connections.py", line 393, in check_error
    err.raise_mysql_exception(self._data)
  File "C:\Users\QX\AppData\Local\Programs\Python\Python35-32\lib\site-packages\pymysql\err.py", line 107, in raise_mysql_exception
    raise errorclass(errno, errval)
django.db.utils.ProgrammingError: (1146, "Table 'kggroup.kf_jobs_coupon_new' doesn't exist")
2017-01-17 21:33:23,883 [Thread-35:19432] [django.request:256] [base:handle_uncaught_exception] [ERROR]- Internal Server Error: /kg/sellcard/fornt/voucher/issue/
Traceback (most recent call last):
  File "C:\Users\QX\AppData\Local\Programs\Python\Python35-32\lib\site-packages\django\db\backends\utils.py", line 64, in execute
    return self.cursor.execute(sql, params)
  File "C:\Users\QX\AppData\Local\Programs\Python\Python35-32\lib\site-packages\django\db\backends\mysql\base.py", line 124, in execute
    return self.cursor.execute(query, args)
  File "C:\Users\QX\AppData\Local\Programs\Python\Python35-32\lib\site-packages\pymysql\cursors.py", line 166, in execute
    result = self._query(query)
  File "C:\Users\QX\AppData\Local\Programs\Python\Python35-32\lib\site-packages\pymysql\cursors.py", line 322, in _query
    conn.query(q)
  File "C:\Users\QX\AppData\Local\Programs\Python\Python35-32\lib\site-packages\pymysql\connections.py", line 835, in query
    self._affected_rows = self._read_query_result(unbuffered=unbuffered)
  File "C:\Users\QX\AppData\Local\Programs\Python\Python35-32\lib\site-packages\pymysql\connections.py", line 1019, in _read_query_result
    result.read()
  File "C:\Users\QX\AppData\Local\Programs\Python\Python35-32\lib\site-packages\pymysql\connections.py", line 1302, in read
    first_packet = self.connection._read_packet()
  File "C:\Users\QX\AppData\Local\Programs\Python\Python35-32\lib\site-packages\pymysql\connections.py", line 981, in _read_packet
    packet.check_error()
  File "C:\Users\QX\AppData\Local\Programs\Python\Python35-32\lib\site-packages\pymysql\connections.py", line 393, in check_error
    err.raise_mysql_exception(self._data)
  File "C:\Users\QX\AppData\Local\Programs\Python\Python35-32\lib\site-packages\pymysql\err.py", line 107, in raise_mysql_exception
    raise errorclass(errno, errval)
pymysql.err.ProgrammingError: (1146, "Table 'kggroup.kf_jobs_coupon_new' doesn't exist")

The above exception was the direct cause of the following exception:

Traceback (most recent call last):
  File "C:\Users\QX\AppData\Local\Programs\Python\Python35-32\lib\site-packages\django\core\handlers\base.py", line 132, in get_response
    response = wrapped_callback(request, *callback_args, **callback_kwargs)
  File "C:\Users\QX\AppData\Local\Programs\Python\Python35-32\lib\contextlib.py", line 30, in inner
    return func(*args, **kwds)
  File "C:\Users\QX\AppData\Local\Programs\Python\Python35-32\lib\contextlib.py", line 30, in inner
    return func(*args, **kwds)
  File "E:/PythonWorkSpace/kggroup\sellcard\fornt\voucher\issue.py", line 70, in index
    return render(request, 'voucher/issue/List.html', locals())
  File "C:\Users\QX\AppData\Local\Programs\Python\Python35-32\lib\site-packages\django\shortcuts.py", line 67, in render
    template_name, context, request=request, using=using)
  File "C:\Users\QX\AppData\Local\Programs\Python\Python35-32\lib\site-packages\django\template\loader.py", line 99, in render_to_string
    return template.render(context, request)
  File "C:\Users\QX\AppData\Local\Programs\Python\Python35-32\lib\site-packages\django\template\backends\django.py", line 74, in render
    return self.template.render(context)
  File "C:\Users\QX\AppData\Local\Programs\Python\Python35-32\lib\site-packages\django\template\base.py", line 209, in render
    return self._render(context)
  File "C:\Users\QX\AppData\Local\Programs\Python\Python35-32\lib\site-packages\django\template\base.py", line 201, in _render
    return self.nodelist.render(context)
  File "C:\Users\QX\AppData\Local\Programs\Python\Python35-32\lib\site-packages\django\template\base.py", line 903, in render
    bit = self.render_node(node, context)
  File "C:\Users\QX\AppData\Local\Programs\Python\Python35-32\lib\site-packages\django\template\base.py", line 917, in render_node
    return node.render(context)
  File "C:\Users\QX\AppData\Local\Programs\Python\Python35-32\lib\site-packages\django\template\defaulttags.py", line 162, in render
    len_values = len(values)
  File "C:\Users\QX\AppData\Local\Programs\Python\Python35-32\lib\site-packages\django\db\models\query.py", line 144, in __len__
    self._fetch_all()
  File "C:\Users\QX\AppData\Local\Programs\Python\Python35-32\lib\site-packages\django\db\models\query.py", line 965, in _fetch_all
    self._result_cache = list(self.iterator())
  File "C:\Users\QX\AppData\Local\Programs\Python\Python35-32\lib\site-packages\django\db\models\query.py", line 1085, in iterator
    for row in self.query.get_compiler(self.db).results_iter():
  File "C:\Users\QX\AppData\Local\Programs\Python\Python35-32\lib\site-packages\django\db\models\sql\compiler.py", line 794, in results_iter
    results = self.execute_sql(MULTI)
  File "C:\Users\QX\AppData\Local\Programs\Python\Python35-32\lib\site-packages\django\db\models\sql\compiler.py", line 840, in execute_sql
    cursor.execute(sql, params)
  File "C:\Users\QX\AppData\Local\Programs\Python\Python35-32\lib\site-packages\django\db\backends\utils.py", line 64, in execute
    return self.cursor.execute(sql, params)
  File "C:\Users\QX\AppData\Local\Programs\Python\Python35-32\lib\site-packages\django\db\utils.py", line 97, in __exit__
    six.reraise(dj_exc_type, dj_exc_value, traceback)
  File "C:\Users\QX\AppData\Local\Programs\Python\Python35-32\lib\site-packages\django\utils\six.py", line 658, in reraise
    raise value.with_traceback(tb)
  File "C:\Users\QX\AppData\Local\Programs\Python\Python35-32\lib\site-packages\django\db\backends\utils.py", line 64, in execute
    return self.cursor.execute(sql, params)
  File "C:\Users\QX\AppData\Local\Programs\Python\Python35-32\lib\site-packages\django\db\backends\mysql\base.py", line 124, in execute
    return self.cursor.execute(query, args)
  File "C:\Users\QX\AppData\Local\Programs\Python\Python35-32\lib\site-packages\pymysql\cursors.py", line 166, in execute
    result = self._query(query)
  File "C:\Users\QX\AppData\Local\Programs\Python\Python35-32\lib\site-packages\pymysql\cursors.py", line 322, in _query
    conn.query(q)
  File "C:\Users\QX\AppData\Local\Programs\Python\Python35-32\lib\site-packages\pymysql\connections.py", line 835, in query
    self._affected_rows = self._read_query_result(unbuffered=unbuffered)
  File "C:\Users\QX\AppData\Local\Programs\Python\Python35-32\lib\site-packages\pymysql\connections.py", line 1019, in _read_query_result
    result.read()
  File "C:\Users\QX\AppData\Local\Programs\Python\Python35-32\lib\site-packages\pymysql\connections.py", line 1302, in read
    first_packet = self.connection._read_packet()
  File "C:\Users\QX\AppData\Local\Programs\Python\Python35-32\lib\site-packages\pymysql\connections.py", line 981, in _read_packet
    packet.check_error()
  File "C:\Users\QX\AppData\Local\Programs\Python\Python35-32\lib\site-packages\pymysql\connections.py", line 393, in check_error
    err.raise_mysql_exception(self._data)
  File "C:\Users\QX\AppData\Local\Programs\Python\Python35-32\lib\site-packages\pymysql\err.py", line 107, in raise_mysql_exception
    raise errorclass(errno, errval)
django.db.utils.ProgrammingError: (1146, "Table 'kggroup.kf_jobs_coupon_new' doesn't exist")
2017-01-17 21:38:10,827 [Thread-41:18556] [django.request:256] [base:handle_uncaught_exception] [ERROR]- Internal Server Error: /kg/sellcard/fornt/voucher/issue/
Traceback (most recent call last):
  File "C:\Users\QX\AppData\Local\Programs\Python\Python35-32\lib\site-packages\django\db\backends\utils.py", line 64, in execute
    return self.cursor.execute(sql, params)
  File "C:\Users\QX\AppData\Local\Programs\Python\Python35-32\lib\site-packages\django\db\backends\mysql\base.py", line 124, in execute
    return self.cursor.execute(query, args)
  File "C:\Users\QX\AppData\Local\Programs\Python\Python35-32\lib\site-packages\pymysql\cursors.py", line 166, in execute
    result = self._query(query)
  File "C:\Users\QX\AppData\Local\Programs\Python\Python35-32\lib\site-packages\pymysql\cursors.py", line 322, in _query
    conn.query(q)
  File "C:\Users\QX\AppData\Local\Programs\Python\Python35-32\lib\site-packages\pymysql\connections.py", line 835, in query
    self._affected_rows = self._read_query_result(unbuffered=unbuffered)
  File "C:\Users\QX\AppData\Local\Programs\Python\Python35-32\lib\site-packages\pymysql\connections.py", line 1019, in _read_query_result
    result.read()
  File "C:\Users\QX\AppData\Local\Programs\Python\Python35-32\lib\site-packages\pymysql\connections.py", line 1302, in read
    first_packet = self.connection._read_packet()
  File "C:\Users\QX\AppData\Local\Programs\Python\Python35-32\lib\site-packages\pymysql\connections.py", line 981, in _read_packet
    packet.check_error()
  File "C:\Users\QX\AppData\Local\Programs\Python\Python35-32\lib\site-packages\pymysql\connections.py", line 393, in check_error
    err.raise_mysql_exception(self._data)
  File "C:\Users\QX\AppData\Local\Programs\Python\Python35-32\lib\site-packages\pymysql\err.py", line 107, in raise_mysql_exception
    raise errorclass(errno, errval)
pymysql.err.ProgrammingError: (1146, "Table 'kggroup.kf_jobs_coupon_new' doesn't exist")

The above exception was the direct cause of the following exception:

Traceback (most recent call last):
  File "C:\Users\QX\AppData\Local\Programs\Python\Python35-32\lib\site-packages\django\core\handlers\base.py", line 132, in get_response
    response = wrapped_callback(request, *callback_args, **callback_kwargs)
  File "C:\Users\QX\AppData\Local\Programs\Python\Python35-32\lib\contextlib.py", line 30, in inner
    return func(*args, **kwds)
  File "C:\Users\QX\AppData\Local\Programs\Python\Python35-32\lib\contextlib.py", line 30, in inner
    return func(*args, **kwds)
  File "E:/PythonWorkSpace/kggroup\sellcard\fornt\voucher\issue.py", line 70, in index
    return render(request, 'voucher/issue/List.html', locals())
  File "C:\Users\QX\AppData\Local\Programs\Python\Python35-32\lib\site-packages\django\shortcuts.py", line 67, in render
    template_name, context, request=request, using=using)
  File "C:\Users\QX\AppData\Local\Programs\Python\Python35-32\lib\site-packages\django\template\loader.py", line 99, in render_to_string
    return template.render(context, request)
  File "C:\Users\QX\AppData\Local\Programs\Python\Python35-32\lib\site-packages\django\template\backends\django.py", line 74, in render
    return self.template.render(context)
  File "C:\Users\QX\AppData\Local\Programs\Python\Python35-32\lib\site-packages\django\template\base.py", line 209, in render
    return self._render(context)
  File "C:\Users\QX\AppData\Local\Programs\Python\Python35-32\lib\site-packages\django\template\base.py", line 201, in _render
    return self.nodelist.render(context)
  File "C:\Users\QX\AppData\Local\Programs\Python\Python35-32\lib\site-packages\django\template\base.py", line 903, in render
    bit = self.render_node(node, context)
  File "C:\Users\QX\AppData\Local\Programs\Python\Python35-32\lib\site-packages\django\template\base.py", line 917, in render_node
    return node.render(context)
  File "C:\Users\QX\AppData\Local\Programs\Python\Python35-32\lib\site-packages\django\template\defaulttags.py", line 162, in render
    len_values = len(values)
  File "C:\Users\QX\AppData\Local\Programs\Python\Python35-32\lib\site-packages\django\db\models\query.py", line 144, in __len__
    self._fetch_all()
  File "C:\Users\QX\AppData\Local\Programs\Python\Python35-32\lib\site-packages\django\db\models\query.py", line 965, in _fetch_all
    self._result_cache = list(self.iterator())
  File "C:\Users\QX\AppData\Local\Programs\Python\Python35-32\lib\site-packages\django\db\models\query.py", line 1085, in iterator
    for row in self.query.get_compiler(self.db).results_iter():
  File "C:\Users\QX\AppData\Local\Programs\Python\Python35-32\lib\site-packages\django\db\models\sql\compiler.py", line 794, in results_iter
    results = self.execute_sql(MULTI)
  File "C:\Users\QX\AppData\Local\Programs\Python\Python35-32\lib\site-packages\django\db\models\sql\compiler.py", line 840, in execute_sql
    cursor.execute(sql, params)
  File "C:\Users\QX\AppData\Local\Programs\Python\Python35-32\lib\site-packages\django\db\backends\utils.py", line 64, in execute
    return self.cursor.execute(sql, params)
  File "C:\Users\QX\AppData\Local\Programs\Python\Python35-32\lib\site-packages\django\db\utils.py", line 97, in __exit__
    six.reraise(dj_exc_type, dj_exc_value, traceback)
  File "C:\Users\QX\AppData\Local\Programs\Python\Python35-32\lib\site-packages\django\utils\six.py", line 658, in reraise
    raise value.with_traceback(tb)
  File "C:\Users\QX\AppData\Local\Programs\Python\Python35-32\lib\site-packages\django\db\backends\utils.py", line 64, in execute
    return self.cursor.execute(sql, params)
  File "C:\Users\QX\AppData\Local\Programs\Python\Python35-32\lib\site-packages\django\db\backends\mysql\base.py", line 124, in execute
    return self.cursor.execute(query, args)
  File "C:\Users\QX\AppData\Local\Programs\Python\Python35-32\lib\site-packages\pymysql\cursors.py", line 166, in execute
    result = self._query(query)
  File "C:\Users\QX\AppData\Local\Programs\Python\Python35-32\lib\site-packages\pymysql\cursors.py", line 322, in _query
    conn.query(q)
  File "C:\Users\QX\AppData\Local\Programs\Python\Python35-32\lib\site-packages\pymysql\connections.py", line 835, in query
    self._affected_rows = self._read_query_result(unbuffered=unbuffered)
  File "C:\Users\QX\AppData\Local\Programs\Python\Python35-32\lib\site-packages\pymysql\connections.py", line 1019, in _read_query_result
    result.read()
  File "C:\Users\QX\AppData\Local\Programs\Python\Python35-32\lib\site-packages\pymysql\connections.py", line 1302, in read
    first_packet = self.connection._read_packet()
  File "C:\Users\QX\AppData\Local\Programs\Python\Python35-32\lib\site-packages\pymysql\connections.py", line 981, in _read_packet
    packet.check_error()
  File "C:\Users\QX\AppData\Local\Programs\Python\Python35-32\lib\site-packages\pymysql\connections.py", line 393, in check_error
    err.raise_mysql_exception(self._data)
  File "C:\Users\QX\AppData\Local\Programs\Python\Python35-32\lib\site-packages\pymysql\err.py", line 107, in raise_mysql_exception
    raise errorclass(errno, errval)
django.db.utils.ProgrammingError: (1146, "Table 'kggroup.kf_jobs_coupon_new' doesn't exist")
2017-01-18 08:50:09,478 [Thread-24:20292] [django.request:256] [base:handle_uncaught_exception] [ERROR]- Internal Server Error: /kg/sellcard/report/voucher/payment/
Traceback (most recent call last):
  File "C:\Users\QX\AppData\Local\Programs\Python\Python35-32\lib\site-packages\django\core\handlers\base.py", line 132, in get_response
    response = wrapped_callback(request, *callback_args, **callback_kwargs)
  File "C:\Users\QX\AppData\Local\Programs\Python\Python35-32\lib\contextlib.py", line 30, in inner
    return func(*args, **kwds)
  File "E:/PythonWorkSpace/kggroup\sellcard\report\voucher\payment.py", line 39, in index
    code_list.append(item_shop['shop_code'])
TypeError: string indices must be integers
2017-01-18 08:50:14,873 [Thread-28:14476] [django.request:256] [base:handle_uncaught_exception] [ERROR]- Internal Server Error: /kg/sellcard/report/voucher/payment/
Traceback (most recent call last):
  File "C:\Users\QX\AppData\Local\Programs\Python\Python35-32\lib\site-packages\django\core\handlers\base.py", line 132, in get_response
    response = wrapped_callback(request, *callback_args, **callback_kwargs)
  File "C:\Users\QX\AppData\Local\Programs\Python\Python35-32\lib\contextlib.py", line 30, in inner
    return func(*args, **kwds)
  File "E:/PythonWorkSpace/kggroup\sellcard\report\voucher\payment.py", line 39, in index
    code_list.append(item_shop['shop_code'])
TypeError: string indices must be integers
2017-01-18 11:06:52,112 [Thread-153:12740] [django.request:170] [base:get_response] [WARNING]- Not Found: /js/jquery.min.map
2017-01-18 11:14:16,679 [Thread-61:5904] [django.request:256] [base:handle_uncaught_exception] [ERROR]- Internal Server Error: /kg/sellcard/report/voucher/payment/
Traceback (most recent call last):
  File "C:\Users\QX\AppData\Local\Programs\Python\Python35-32\lib\site-packages\django\core\handlers\base.py", line 132, in get_response
    response = wrapped_callback(request, *callback_args, **callback_kwargs)
  File "C:\Users\QX\AppData\Local\Programs\Python\Python35-32\lib\contextlib.py", line 30, in inner
    return func(*args, **kwds)
  File "E:/PythonWorkSpace/kggroup\sellcard\report\voucher\payment.py", line 39, in index
    code_list.append(item_shop['shop_code'])
TypeError: string indices must be integers
2017-01-18 11:33:30,566 [Thread-9:10836] [django.request:256] [base:handle_uncaught_exception] [ERROR]- Internal Server Error: /kg/sellcard/report/voucher/used/
Traceback (most recent call last):
  File "C:\Users\QX\AppData\Local\Programs\Python\Python35-32\lib\site-packages\django\core\handlers\base.py", line 132, in get_response
    response = wrapped_callback(request, *callback_args, **callback_kwargs)
  File "C:\Users\QX\AppData\Local\Programs\Python\Python35-32\lib\contextlib.py", line 30, in inner
    return func(*args, **kwds)
  File "E:/PythonWorkSpace/kggroup\sellcard\report\voucher\used.py", line 40, in index
    code_list.append(shops.get(shop_code=shopcode)['shop_code'])
  File "C:\Users\QX\AppData\Local\Programs\Python\Python35-32\lib\site-packages\django\db\models\query.py", line 334, in get
    self.model._meta.object_name
sellcard.models.DoesNotExist: Shops matching query does not exist.
2017-01-18 11:33:36,340 [Thread-13:1452] [django.request:256] [base:handle_uncaught_exception] [ERROR]- Internal Server Error: /kg/sellcard/report/voucher/used/
Traceback (most recent call last):
  File "C:\Users\QX\AppData\Local\Programs\Python\Python35-32\lib\site-packages\django\core\handlers\base.py", line 132, in get_response
    response = wrapped_callback(request, *callback_args, **callback_kwargs)
  File "C:\Users\QX\AppData\Local\Programs\Python\Python35-32\lib\contextlib.py", line 30, in inner
    return func(*args, **kwds)
  File "E:/PythonWorkSpace/kggroup\sellcard\report\voucher\used.py", line 40, in index
    code_list.append(shops.get(shop_code=shopcode)['shop_code'])
  File "C:\Users\QX\AppData\Local\Programs\Python\Python35-32\lib\site-packages\django\db\models\query.py", line 334, in get
    self.model._meta.object_name
sellcard.models.DoesNotExist: Shops matching query does not exist.
2017-01-18 11:34:21,710 [Thread-17:6728] [django.request:256] [base:handle_uncaught_exception] [ERROR]- Internal Server Error: /kg/sellcard/report/voucher/used/
Traceback (most recent call last):
  File "C:\Users\QX\AppData\Local\Programs\Python\Python35-32\lib\site-packages\django\core\handlers\base.py", line 132, in get_response
    response = wrapped_callback(request, *callback_args, **callback_kwargs)
  File "C:\Users\QX\AppData\Local\Programs\Python\Python35-32\lib\contextlib.py", line 30, in inner
    return func(*args, **kwds)
  File "E:/PythonWorkSpace/kggroup\sellcard\report\voucher\used.py", line 40, in index
    code_list.append(shops.get(shop_code=shopcode)['shop_code'])
  File "C:\Users\QX\AppData\Local\Programs\Python\Python35-32\lib\site-packages\django\db\models\query.py", line 334, in get
    self.model._meta.object_name
sellcard.models.DoesNotExist: Shops matching query does not exist.
2017-01-18 11:36:41,855 [Thread-10:12476] [django.request:256] [base:handle_uncaught_exception] [ERROR]- Internal Server Error: /kg/sellcard/report/voucher/used/detail/
Traceback (most recent call last):
  File "C:\Users\QX\AppData\Local\Programs\Python\Python35-32\lib\site-packages\django\core\handlers\base.py", line 132, in get_response
    response = wrapped_callback(request, *callback_args, **callback_kwargs)
  File "C:\Users\QX\AppData\Local\Programs\Python\Python35-32\lib\contextlib.py", line 30, in inner
    return func(*args, **kwds)
  File "E:/PythonWorkSpace/kggroup\sellcard\report\voucher\used.py", line 138, in detail
    code_list.append(shops.get(shop_code=shop_code)['shop_code'])
  File "C:\Users\QX\AppData\Local\Programs\Python\Python35-32\lib\site-packages\django\db\models\query.py", line 334, in get
    self.model._meta.object_name
sellcard.models.DoesNotExist: Shops matching query does not exist.
2017-01-18 11:39:20,044 [Thread-22:13644] [django.request:256] [base:handle_uncaught_exception] [ERROR]- Internal Server Error: /kg/sellcard/report/voucher/used/detail/
Traceback (most recent call last):
  File "C:\Users\QX\AppData\Local\Programs\Python\Python35-32\lib\site-packages\django\core\handlers\base.py", line 132, in get_response
    response = wrapped_callback(request, *callback_args, **callback_kwargs)
  File "C:\Users\QX\AppData\Local\Programs\Python\Python35-32\lib\contextlib.py", line 30, in inner
    return func(*args, **kwds)
  File "E:/PythonWorkSpace/kggroup\sellcard\report\voucher\used.py", line 138, in detail
    code_list.append(shops.get(shop_code=shop_code)['shop_code'])
  File "C:\Users\QX\AppData\Local\Programs\Python\Python35-32\lib\site-packages\django\db\models\query.py", line 334, in get
    self.model._meta.object_name
sellcard.models.DoesNotExist: Shops matching query does not exist.
2017-01-18 11:40:38,186 [Thread-29:3140] [django.request:256] [base:handle_uncaught_exception] [ERROR]- Internal Server Error: /kg/sellcard/report/voucher/used/detail/
Traceback (most recent call last):
  File "C:\Users\QX\AppData\Local\Programs\Python\Python35-32\lib\site-packages\django\core\handlers\base.py", line 132, in get_response
    response = wrapped_callback(request, *callback_args, **callback_kwargs)
  File "C:\Users\QX\AppData\Local\Programs\Python\Python35-32\lib\contextlib.py", line 30, in inner
    return func(*args, **kwds)
  File "E:/PythonWorkSpace/kggroup\sellcard\report\voucher\used.py", line 138, in detail
    code_list.append(shops.get(shop_code=shop_code)['shop_code'])
  File "C:\Users\QX\AppData\Local\Programs\Python\Python35-32\lib\site-packages\django\db\models\query.py", line 334, in get
    self.model._meta.object_name
sellcard.models.DoesNotExist: Shops matching query does not exist.
2017-01-18 11:41:12,095 [Thread-36:9844] [django.request:256] [base:handle_uncaught_exception] [ERROR]- Internal Server Error: /kg/sellcard/report/voucher/used/detail/
Traceback (most recent call last):
  File "C:\Users\QX\AppData\Local\Programs\Python\Python35-32\lib\site-packages\django\core\handlers\base.py", line 132, in get_response
    response = wrapped_callback(request, *callback_args, **callback_kwargs)
  File "C:\Users\QX\AppData\Local\Programs\Python\Python35-32\lib\contextlib.py", line 30, in inner
    return func(*args, **kwds)
  File "E:/PythonWorkSpace/kggroup\sellcard\report\voucher\used.py", line 138, in detail
    code_list.append(shops.get(shop_code=shop_code)['shop_code'])
  File "C:\Users\QX\AppData\Local\Programs\Python\Python35-32\lib\site-packages\django\db\models\query.py", line 334, in get
    self.model._meta.object_name
sellcard.models.DoesNotExist: Shops matching query does not exist.
2017-01-18 11:58:27,677 [Thread-29:13084] [django.request:256] [base:handle_uncaught_exception] [ERROR]- Internal Server Error: /kg/sellcard/report/voucher/payment/
Traceback (most recent call last):
  File "C:\Users\QX\AppData\Local\Programs\Python\Python35-32\lib\site-packages\django\core\handlers\base.py", line 132, in get_response
    response = wrapped_callback(request, *callback_args, **callback_kwargs)
  File "C:\Users\QX\AppData\Local\Programs\Python\Python35-32\lib\contextlib.py", line 30, in inner
    return func(*args, **kwds)
  File "E:/PythonWorkSpace/kggroup\sellcard\report\voucher\payment.py", line 39, in index
    code_list.append(item_shop['shop_code'])
TypeError: string indices must be integers
2017-01-18 11:59:51,949 [Thread-34:4140] [django.request:256] [base:handle_uncaught_exception] [ERROR]- Internal Server Error: /kg/sellcard/report/voucher/payment/
Traceback (most recent call last):
  File "C:\Users\QX\AppData\Local\Programs\Python\Python35-32\lib\site-packages\django\core\handlers\base.py", line 132, in get_response
    response = wrapped_callback(request, *callback_args, **callback_kwargs)
  File "C:\Users\QX\AppData\Local\Programs\Python\Python35-32\lib\contextlib.py", line 30, in inner
    return func(*args, **kwds)
  File "E:/PythonWorkSpace/kggroup\sellcard\report\voucher\payment.py", line 39, in index
    code_list.append(item_shop['shop_code'])
TypeError: string indices must be integers
2017-01-18 12:01:01,266 [Thread-39:17880] [django.request:256] [base:handle_uncaught_exception] [ERROR]- Internal Server Error: /kg/sellcard/report/voucher/payment/
Traceback (most recent call last):
  File "C:\Users\QX\AppData\Local\Programs\Python\Python35-32\lib\site-packages\django\core\handlers\base.py", line 132, in get_response
    response = wrapped_callback(request, *callback_args, **callback_kwargs)
  File "C:\Users\QX\AppData\Local\Programs\Python\Python35-32\lib\contextlib.py", line 30, in inner
    return func(*args, **kwds)
  File "E:/PythonWorkSpace/kggroup\sellcard\report\voucher\payment.py", line 39, in index
    code_list.append(item_shop['shop_code'])
TypeError: string indices must be integers
2017-01-18 12:01:36,894 [Thread-44:14048] [django.request:256] [base:handle_uncaught_exception] [ERROR]- Internal Server Error: /kg/sellcard/report/voucher/payment/
Traceback (most recent call last):
  File "C:\Users\QX\AppData\Local\Programs\Python\Python35-32\lib\site-packages\django\core\handlers\base.py", line 132, in get_response
    response = wrapped_callback(request, *callback_args, **callback_kwargs)
  File "C:\Users\QX\AppData\Local\Programs\Python\Python35-32\lib\contextlib.py", line 30, in inner
    return func(*args, **kwds)
  File "E:/PythonWorkSpace/kggroup\sellcard\report\voucher\payment.py", line 39, in index
    code_list.append(item_shop['shop_code'])
TypeError: string indices must be integers
2017-01-18 12:15:13,167 [Thread-9:10028] [django.request:256] [base:handle_uncaught_exception] [ERROR]- Internal Server Error: /kg/sellcard/report/voucher/used/
Traceback (most recent call last):
  File "C:\Users\QX\AppData\Local\Programs\Python\Python35-32\lib\site-packages\django\core\handlers\base.py", line 132, in get_response
    response = wrapped_callback(request, *callback_args, **callback_kwargs)
  File "C:\Users\QX\AppData\Local\Programs\Python\Python35-32\lib\contextlib.py", line 30, in inner
    return func(*args, **kwds)
  File "E:/PythonWorkSpace/kggroup\sellcard\report\voucher\used.py", line 41, in index
    code_list.append(shops.get(shop_code=shopcode)['shop_code'])
  File "C:\Users\QX\AppData\Local\Programs\Python\Python35-32\lib\site-packages\django\db\models\query.py", line 334, in get
    self.model._meta.object_name
sellcard.models.DoesNotExist: Shops matching query does not exist.
2017-01-19 15:35:07,273 [Thread-7:9668] [django.request:170] [base:get_response] [WARNING]- Not Found: /
2017-01-20 08:52:02,359 [Thread-15:6232] [django.request:170] [base:get_response] [WARNING]- Not Found: /kg/sellcard/index/favicon.ico
2017-01-20 08:52:31,816 [Thread-23:4480] [django.request:170] [base:get_response] [WARNING]- Not Found: /js/j   var orderVal = cardOutTotalVal + discPay;    $('.Total 
2017-01-20 08:52:33,905 [Thread-24:7108] [django.request:170] [base:get_response] [WARNING]- Not Found: /favicon.ico
2017-01-20 08:52:36,047 [Thread-25:2804] [django.request:170] [base:get_response] [WARNING]- Not Found: /favicon.ico
2017-01-20 09:05:42,683 [Thread-37:2376] [django.request:170] [base:get_response] [WARNING]- Not Found: /kg/sellcard/fornt/bestowed/favicon.ico
2017-01-20 09:05:44,827 [Thread-38:4100] [django.request:170] [base:get_response] [WARNING]- Not Found: /kg/sellcard/fornt/bestowed/favicon.ico
2017-01-21 09:30:27,248 [Thread-14:10436] [django.request:170] [base:get_response] [WARNING]- Not Found: /js/table-my..js
2017-01-21 09:30:45,139 [Thread-35:12628] [django.request:170] [base:get_response] [WARNING]- Not Found: /kg/sellcard/report/card/kgsale/shop/favicon.ico
2017-01-21 09:31:12,005 [Thread-39:1508] [django.request:170] [base:get_response] [WARNING]- Not Found: /kg/sellcard/report/card/kgsale/shop/d/favicon.ico
2017-01-21 09:31:12,418 [Thread-40:5452] [django.request:170] [base:get_response] [WARNING]- Not Found: /kg/sellcard/report/card/kgsale/shop/d/favicon.ico
2017-01-21 09:47:21,803 [Thread-26:13576] [django.request:256] [base:handle_uncaught_exception] [ERROR]- Internal Server Error: /kg/sellcard/report/card/kgsale/shop/nopay/
Traceback (most recent call last):
  File "C:\Python34\lib\site-packages\django\template\base.py", line 819, in _resolve_lookup
    current = current[bit]
  File "C:\Python34\lib\site-packages\django\template\context.py", line 71, in __getitem__
    raise KeyError(key)
KeyError: 'totalDict'

During handling of the above exception, another exception occurred:

Traceback (most recent call last):
  File "C:\Python34\lib\site-packages\django\template\base.py", line 825, in _resolve_lookup
    if isinstance(current, BaseContext) and getattr(type(current), bit):
AttributeError: type object 'RequestContext' has no attribute 'totalDict'

During handling of the above exception, another exception occurred:

Traceback (most recent call last):
  File "C:\Python34\lib\site-packages\django\template\base.py", line 834, in _resolve_lookup
    current = current[int(bit)]
ValueError: invalid literal for int() with base 10: 'totalDict'

During handling of the above exception, another exception occurred:

Traceback (most recent call last):
  File "C:\Python34\lib\site-packages\django\core\handlers\base.py", line 132, in get_response
    response = wrapped_callback(request, *callback_args, **callback_kwargs)
  File "C:\Python34\lib\contextlib.py", line 30, in inner
    return func(*args, **kwds)
  File "D:/python/project/kggroup\sellcard\report\card\saleGroupByShop.py", line 219, in noPay
    return render(request,'report/card/saleGroupByShop/noPay.html', locals())
  File "C:\Python34\lib\site-packages\django\shortcuts.py", line 67, in render
    template_name, context, request=request, using=using)
  File "C:\Python34\lib\site-packages\django\template\loader.py", line 99, in render_to_string
    return template.render(context, request)
  File "C:\Python34\lib\site-packages\django\template\backends\django.py", line 74, in render
    return self.template.render(context)
  File "C:\Python34\lib\site-packages\django\template\base.py", line 210, in render
    return self._render(context)
  File "C:\Python34\lib\site-packages\django\template\base.py", line 202, in _render
    return self.nodelist.render(context)
  File "C:\Python34\lib\site-packages\django\template\base.py", line 905, in render
    bit = self.render_node(node, context)
  File "C:\Python34\lib\site-packages\django\template\base.py", line 919, in render_node
    return node.render(context)
  File "C:\Python34\lib\site-packages\django\template\base.py", line 959, in render
    output = self.filter_expression.resolve(context)
  File "C:\Python34\lib\site-packages\django\template\base.py", line 669, in resolve
    arg_vals.append(arg.resolve(context))
  File "C:\Python34\lib\site-packages\django\template\base.py", line 789, in resolve
    value = self._resolve_lookup(context)
  File "C:\Python34\lib\site-packages\django\template\base.py", line 841, in _resolve_lookup
    (bit, current))  # missing attribute
django.template.base.VariableDoesNotExist: Failed lookup for key [totalDict] in "[{'None': None, 'True': True, 'False': False}, {}, {}, {'request': <WSGIRequest: GET '/kg/sellcard/report/card/kgsale/shop/nopay/'>}]"
2017-01-21 09:47:22,059 [Thread-27:11856] [django.request:170] [base:get_response] [WARNING]- Not Found: /kg/sellcard/report/card/kgsale/shop/nopay/favicon.ico
2017-01-21 09:47:22,745 [Thread-28:11504] [django.request:170] [base:get_response] [WARNING]- Not Found: /kg/sellcard/report/card/kgsale/shop/nopay/favicon.ico
2017-01-21 09:47:57,293 [Thread-7:13892] [django.request:256] [base:handle_uncaught_exception] [ERROR]- Internal Server Error: /kg/sellcard/report/card/kgsale/shop/nopay/
Traceback (most recent call last):
  File "C:\Python34\lib\site-packages\django\template\base.py", line 819, in _resolve_lookup
    current = current[bit]
  File "C:\Python34\lib\site-packages\django\template\context.py", line 71, in __getitem__
    raise KeyError(key)
KeyError: 'totalDict'

During handling of the above exception, another exception occurred:

Traceback (most recent call last):
  File "C:\Python34\lib\site-packages\django\template\base.py", line 825, in _resolve_lookup
    if isinstance(current, BaseContext) and getattr(type(current), bit):
AttributeError: type object 'RequestContext' has no attribute 'totalDict'

During handling of the above exception, another exception occurred:

Traceback (most recent call last):
  File "C:\Python34\lib\site-packages\django\template\base.py", line 834, in _resolve_lookup
    current = current[int(bit)]
ValueError: invalid literal for int() with base 10: 'totalDict'

During handling of the above exception, another exception occurred:

Traceback (most recent call last):
  File "C:\Python34\lib\site-packages\django\core\handlers\base.py", line 132, in get_response
    response = wrapped_callback(request, *callback_args, **callback_kwargs)
  File "C:\Python34\lib\contextlib.py", line 30, in inner
    return func(*args, **kwds)
  File "D:/python/project/kggroup\sellcard\report\card\saleGroupByShop.py", line 219, in noPay
    return render(request,'report/card/saleGroupByShop/noPay.html', locals())
  File "C:\Python34\lib\site-packages\django\shortcuts.py", line 67, in render
    template_name, context, request=request, using=using)
  File "C:\Python34\lib\site-packages\django\template\loader.py", line 99, in render_to_string
    return template.render(context, request)
  File "C:\Python34\lib\site-packages\django\template\backends\django.py", line 74, in render
    return self.template.render(context)
  File "C:\Python34\lib\site-packages\django\template\base.py", line 210, in render
    return self._render(context)
  File "C:\Python34\lib\site-packages\django\template\base.py", line 202, in _render
    return self.nodelist.render(context)
  File "C:\Python34\lib\site-packages\django\template\base.py", line 905, in render
    bit = self.render_node(node, context)
  File "C:\Python34\lib\site-packages\django\template\debug.py", line 79, in render_node
    return node.render(context)
  File "C:\Python34\lib\site-packages\django\template\debug.py", line 89, in render
    output = self.filter_expression.resolve(context)
  File "C:\Python34\lib\site-packages\django\template\base.py", line 669, in resolve
    arg_vals.append(arg.resolve(context))
  File "C:\Python34\lib\site-packages\django\template\base.py", line 789, in resolve
    value = self._resolve_lookup(context)
  File "C:\Python34\lib\site-packages\django\template\base.py", line 841, in _resolve_lookup
    (bit, current))  # missing attribute
django.template.base.VariableDoesNotExist: Failed lookup for key [totalDict] in "[{'None': None, 'True': True, 'False': False}, {}, {}, {'request': <WSGIRequest: GET '/kg/sellcard/report/card/kgsale/shop/nopay/'>}]"
2017-01-21 10:02:00,526 [Thread-7:13904] [django.request:170] [base:get_response] [WARNING]- Not Found: /
2017-01-21 10:02:08,898 [Thread-9:10224] [django.request:170] [base:get_response] [WARNING]- Not Found: /kg/sellcard/fornt/nopay/ordinary/favicon.ico
2017-01-21 10:02:09,009 [Thread-10:4344] [django.request:170] [base:get_response] [WARNING]- Not Found: /kg/sellcard/fornt/nopay/ordinary/favicon.ico
2017-01-21 10:05:11,821 [Thread-19:13452] [django.request:170] [base:get_response] [WARNING]- Not Found: /kg/sellcard/fornt/cardsale/favicon.ico
2017-01-21 10:05:11,894 [Thread-20:12464] [django.request:170] [base:get_response] [WARNING]- Not Found: /kg/sellcard/fornt/cardsale/favicon.ico
2017-01-21 10:29:44,958 [Thread-250:10808] [django.request:170] [base:get_response] [WARNING]- Not Found: /js/jquery.min.map
2017-01-21 10:31:26,131 [Thread-271:10916] [django.request:170] [base:get_response] [WARNING]- Not Found: /js/jquery.min.map
2017-01-21 10:31:44,504 [Thread-291:11444] [django.request:170] [base:get_response] [WARNING]- Not Found: /js/jquery.min.map
2017-01-21 10:32:04,828 [Thread-311:12648] [django.request:170] [base:get_response] [WARNING]- Not Found: /js/jquery.min.map
2017-01-21 10:32:36,537 [Thread-331:712] [django.request:170] [base:get_response] [WARNING]- Not Found: /js/jquery.min.map
2017-01-21 10:35:44,087 [Thread-351:5104] [django.request:170] [base:get_response] [WARNING]- Not Found: /js/jquery.min.map
2017-01-21 10:36:09,829 [Thread-371:10916] [django.request:170] [base:get_response] [WARNING]- Not Found: /js/jquery.min.map
2017-01-21 10:36:21,191 [Thread-391:492] [django.request:170] [base:get_response] [WARNING]- Not Found: /js/jquery.min.map
2017-01-21 10:36:50,998 [Thread-411:10888] [django.request:170] [base:get_response] [WARNING]- Not Found: /js/jquery.min.map
2017-01-21 10:37:05,139 [Thread-431:13596] [django.request:170] [base:get_response] [WARNING]- Not Found: /js/jquery.min.map
2017-01-21 10:52:37,505 [Thread-7:10736] [django.request:256] [base:handle_uncaught_exception] [ERROR]- Internal Server Error: /kg/sellcard/report/card/kgsale/shop/nopay/
Traceback (most recent call last):
  File "C:\Python34\lib\site-packages\django\core\handlers\base.py", line 132, in get_response
    response = wrapped_callback(request, *callback_args, **callback_kwargs)
  File "C:\Python34\lib\contextlib.py", line 30, in inner
    return func(*args, **kwds)
  File "D:/python/project/kggroup\sellcard\report\card\saleGroupByShop.py", line 222, in noPay
    endTime = str(datetime.datetime.strptime(end, '%Y-%m-%d').date() + datetime.timedelta(1))
TypeError: must be str, not datetime.date
2017-01-21 10:52:47,635 [Thread-7:13536] [django.request:170] [base:get_response] [WARNING]- Not Found: /js/jquery.min.map
2017-01-21 10:52:51,828 [Thread-25:11872] [django.request:170] [base:get_response] [WARNING]- Not Found: /js/jquery.min.map
2017-01-21 10:53:05,342 [Thread-28:12572] [django.request:256] [base:handle_uncaught_exception] [ERROR]- Internal Server Error: /kg/sellcard/report/card/kgsale/shop/nopay/
Traceback (most recent call last):
  File "C:\Python34\lib\site-packages\django\core\handlers\base.py", line 132, in get_response
    response = wrapped_callback(request, *callback_args, **callback_kwargs)
  File "C:\Python34\lib\contextlib.py", line 30, in inner
    return func(*args, **kwds)
  File "D:/python/project/kggroup\sellcard\report\card\saleGroupByShop.py", line 231, in noPay
    list = cur.execute(saleSql)
  File "C:\Python34\lib\site-packages\pymysql\cursors.py", line 158, in execute
    result = self._query(query)
  File "C:\Python34\lib\site-packages\pymysql\cursors.py", line 308, in _query
    conn.query(q)
  File "C:\Python34\lib\site-packages\pymysql\connections.py", line 820, in query
    self._affected_rows = self._read_query_result(unbuffered=unbuffered)
  File "C:\Python34\lib\site-packages\pymysql\connections.py", line 1002, in _read_query_result
    result.read()
  File "C:\Python34\lib\site-packages\pymysql\connections.py", line 1285, in read
    first_packet = self.connection._read_packet()
  File "C:\Python34\lib\site-packages\pymysql\connections.py", line 966, in _read_packet
    packet.check_error()
  File "C:\Python34\lib\site-packages\pymysql\connections.py", line 394, in check_error
    err.raise_mysql_exception(self._data)
  File "C:\Python34\lib\site-packages\pymysql\err.py", line 120, in raise_mysql_exception
    _check_mysql_exception(errinfo)
  File "C:\Python34\lib\site-packages\pymysql\err.py", line 115, in _check_mysql_exception
    raise InternalError(errno, errorvalue)
pymysql.err.InternalError: (1054, "Unknown column 'C001' in 'where clause'")
2017-01-21 10:53:42,108 [Thread-7:10596] [django.request:256] [base:handle_uncaught_exception] [ERROR]- Internal Server Error: /kg/sellcard/report/card/kgsale/shop/nopay/
Traceback (most recent call last):
  File "C:\Python34\lib\site-packages\django\core\handlers\base.py", line 132, in get_response
    response = wrapped_callback(request, *callback_args, **callback_kwargs)
  File "C:\Python34\lib\contextlib.py", line 30, in inner
    return func(*args, **kwds)
  File "D:/python/project/kggroup\sellcard\report\card\saleGroupByShop.py", line 231, in noPay
    list = cur.execute(saleSql)
  File "C:\Python34\lib\site-packages\pymysql\cursors.py", line 158, in execute
    result = self._query(query)
  File "C:\Python34\lib\site-packages\pymysql\cursors.py", line 308, in _query
    conn.query(q)
  File "C:\Python34\lib\site-packages\pymysql\connections.py", line 820, in query
    self._affected_rows = self._read_query_result(unbuffered=unbuffered)
  File "C:\Python34\lib\site-packages\pymysql\connections.py", line 1002, in _read_query_result
    result.read()
  File "C:\Python34\lib\site-packages\pymysql\connections.py", line 1285, in read
    first_packet = self.connection._read_packet()
  File "C:\Python34\lib\site-packages\pymysql\connections.py", line 966, in _read_packet
    packet.check_error()
  File "C:\Python34\lib\site-packages\pymysql\connections.py", line 394, in check_error
    err.raise_mysql_exception(self._data)
  File "C:\Python34\lib\site-packages\pymysql\err.py", line 120, in raise_mysql_exception
    _check_mysql_exception(errinfo)
  File "C:\Python34\lib\site-packages\pymysql\err.py", line 115, in _check_mysql_exception
    raise InternalError(errno, errorvalue)
pymysql.err.InternalError: (1054, "Unknown column 'ord.change_time' in 'where clause'")
2017-01-21 10:54:37,235 [Thread-25:10808] [django.request:170] [base:get_response] [WARNING]- Not Found: /js/jquery.min.map
2017-01-21 11:41:47,462 [Thread-25:12936] [django.request:170] [base:get_response] [WARNING]- Not Found: /js/jquery.min.map
2017-01-21 11:45:06,792 [Thread-20:9804] [django.request:170] [base:get_response] [WARNING]- Not Found: /js/table-my..js
2017-01-21 11:45:06,918 [Thread-22:10900] [django.request:170] [base:get_response] [WARNING]- Not Found: /js/jquery.min.map
2017-01-21 11:45:32,017 [Thread-26:5700] [django.request:170] [base:get_response] [WARNING]- Not Found: /js/jquery.min.map
2017-01-21 11:45:46,265 [Thread-28:12716] [django.request:256] [base:handle_uncaught_exception] [ERROR]- Internal Server Error: /kg/sellcard/report/card/kgsale/shop/
Traceback (most recent call last):
  File "C:\Python34\lib\site-packages\django\db\backends\utils.py", line 64, in execute
    return self.cursor.execute(sql, params)
  File "C:\Python34\lib\site-packages\django\db\backends\mysql\base.py", line 124, in execute
    return self.cursor.execute(query, args)
  File "C:\Python34\lib\site-packages\pymysql\cursors.py", line 158, in execute
    result = self._query(query)
  File "C:\Python34\lib\site-packages\pymysql\cursors.py", line 308, in _query
    conn.query(q)
  File "C:\Python34\lib\site-packages\pymysql\connections.py", line 820, in query
    self._affected_rows = self._read_query_result(unbuffered=unbuffered)
  File "C:\Python34\lib\site-packages\pymysql\connections.py", line 1002, in _read_query_result
    result.read()
  File "C:\Python34\lib\site-packages\pymysql\connections.py", line 1285, in read
    first_packet = self.connection._read_packet()
  File "C:\Python34\lib\site-packages\pymysql\connections.py", line 966, in _read_packet
    packet.check_error()
  File "C:\Python34\lib\site-packages\pymysql\connections.py", line 394, in check_error
    err.raise_mysql_exception(self._data)
  File "C:\Python34\lib\site-packages\pymysql\err.py", line 120, in raise_mysql_exception
    _check_mysql_exception(errinfo)
  File "C:\Python34\lib\site-packages\pymysql\err.py", line 115, in _check_mysql_exception
    raise InternalError(errno, errorvalue)
pymysql.err.InternalError: (1054, "Unknown column 'payment.dis_rate' in 'field list'")

The above exception was the direct cause of the following exception:

Traceback (most recent call last):
  File "C:\Python34\lib\site-packages\django\core\handlers\base.py", line 132, in get_response
    response = wrapped_callback(request, *callback_args, **callback_kwargs)
  File "C:\Python34\lib\contextlib.py", line 30, in inner
    return func(*args, **kwds)
  File "D:/python/project/kggroup\sellcard\report\card\saleGroupByShop.py", line 81, in index
    paymentsRateDict = {item['id']: float(item['dis_rate']) for item in paymentsRate}
  File "C:\Python34\lib\site-packages\django\db\models\query.py", line 162, in __iter__
    self._fetch_all()
  File "C:\Python34\lib\site-packages\django\db\models\query.py", line 965, in _fetch_all
    self._result_cache = list(self.iterator())
  File "C:\Python34\lib\site-packages\django\db\models\query.py", line 1085, in iterator
    for row in self.query.get_compiler(self.db).results_iter():
  File "C:\Python34\lib\site-packages\django\db\models\sql\compiler.py", line 794, in results_iter
    results = self.execute_sql(MULTI)
  File "C:\Python34\lib\site-packages\django\db\models\sql\compiler.py", line 840, in execute_sql
    cursor.execute(sql, params)
  File "C:\Python34\lib\site-packages\django\db\backends\utils.py", line 79, in execute
    return super(CursorDebugWrapper, self).execute(sql, params)
  File "C:\Python34\lib\site-packages\django\db\backends\utils.py", line 64, in execute
    return self.cursor.execute(sql, params)
  File "C:\Python34\lib\site-packages\django\db\utils.py", line 98, in __exit__
    six.reraise(dj_exc_type, dj_exc_value, traceback)
  File "C:\Python34\lib\site-packages\django\utils\six.py", line 658, in reraise
    raise value.with_traceback(tb)
  File "C:\Python34\lib\site-packages\django\db\backends\utils.py", line 64, in execute
    return self.cursor.execute(sql, params)
  File "C:\Python34\lib\site-packages\django\db\backends\mysql\base.py", line 124, in execute
    return self.cursor.execute(query, args)
  File "C:\Python34\lib\site-packages\pymysql\cursors.py", line 158, in execute
    result = self._query(query)
  File "C:\Python34\lib\site-packages\pymysql\cursors.py", line 308, in _query
    conn.query(q)
  File "C:\Python34\lib\site-packages\pymysql\connections.py", line 820, in query
    self._affected_rows = self._read_query_result(unbuffered=unbuffered)
  File "C:\Python34\lib\site-packages\pymysql\connections.py", line 1002, in _read_query_result
    result.read()
  File "C:\Python34\lib\site-packages\pymysql\connections.py", line 1285, in read
    first_packet = self.connection._read_packet()
  File "C:\Python34\lib\site-packages\pymysql\connections.py", line 966, in _read_packet
    packet.check_error()
  File "C:\Python34\lib\site-packages\pymysql\connections.py", line 394, in check_error
    err.raise_mysql_exception(self._data)
  File "C:\Python34\lib\site-packages\pymysql\err.py", line 120, in raise_mysql_exception
    _check_mysql_exception(errinfo)
  File "C:\Python34\lib\site-packages\pymysql\err.py", line 115, in _check_mysql_exception
    raise InternalError(errno, errorvalue)
django.db.utils.InternalError: (1054, "Unknown column 'payment.dis_rate' in 'field list'")
2017-01-21 11:46:01,180 [Thread-29:12728] [django.request:170] [base:get_response] [WARNING]- Not Found: /js/jquery.min.map
2017-01-21 11:46:07,365 [Thread-30:13748] [django.request:256] [base:handle_uncaught_exception] [ERROR]- Internal Server Error: /kg/sellcard/report/card/kgsale/shop/
Traceback (most recent call last):
  File "C:\Python34\lib\site-packages\django\db\backends\utils.py", line 64, in execute
    return self.cursor.execute(sql, params)
  File "C:\Python34\lib\site-packages\django\db\backends\mysql\base.py", line 124, in execute
    return self.cursor.execute(query, args)
  File "C:\Python34\lib\site-packages\pymysql\cursors.py", line 158, in execute
    result = self._query(query)
  File "C:\Python34\lib\site-packages\pymysql\cursors.py", line 308, in _query
    conn.query(q)
  File "C:\Python34\lib\site-packages\pymysql\connections.py", line 820, in query
    self._affected_rows = self._read_query_result(unbuffered=unbuffered)
  File "C:\Python34\lib\site-packages\pymysql\connections.py", line 1002, in _read_query_result
    result.read()
  File "C:\Python34\lib\site-packages\pymysql\connections.py", line 1285, in read
    first_packet = self.connection._read_packet()
  File "C:\Python34\lib\site-packages\pymysql\connections.py", line 966, in _read_packet
    packet.check_error()
  File "C:\Python34\lib\site-packages\pymysql\connections.py", line 394, in check_error
    err.raise_mysql_exception(self._data)
  File "C:\Python34\lib\site-packages\pymysql\err.py", line 120, in raise_mysql_exception
    _check_mysql_exception(errinfo)
  File "C:\Python34\lib\site-packages\pymysql\err.py", line 115, in _check_mysql_exception
    raise InternalError(errno, errorvalue)
pymysql.err.InternalError: (1054, "Unknown column 'payment.dis_rate' in 'field list'")

The above exception was the direct cause of the following exception:

Traceback (most recent call last):
  File "C:\Python34\lib\site-packages\django\core\handlers\base.py", line 132, in get_response
    response = wrapped_callback(request, *callback_args, **callback_kwargs)
  File "C:\Python34\lib\contextlib.py", line 30, in inner
    return func(*args, **kwds)
  File "D:/python/project/kggroup\sellcard\report\card\saleGroupByShop.py", line 81, in index
    paymentsRateDict = {item['id']: float(item['dis_rate']) for item in paymentsRate}
  File "C:\Python34\lib\site-packages\django\db\models\query.py", line 162, in __iter__
    self._fetch_all()
  File "C:\Python34\lib\site-packages\django\db\models\query.py", line 965, in _fetch_all
    self._result_cache = list(self.iterator())
  File "C:\Python34\lib\site-packages\django\db\models\query.py", line 1085, in iterator
    for row in self.query.get_compiler(self.db).results_iter():
  File "C:\Python34\lib\site-packages\django\db\models\sql\compiler.py", line 794, in results_iter
    results = self.execute_sql(MULTI)
  File "C:\Python34\lib\site-packages\django\db\models\sql\compiler.py", line 840, in execute_sql
    cursor.execute(sql, params)
  File "C:\Python34\lib\site-packages\django\db\backends\utils.py", line 79, in execute
    return super(CursorDebugWrapper, self).execute(sql, params)
  File "C:\Python34\lib\site-packages\django\db\backends\utils.py", line 64, in execute
    return self.cursor.execute(sql, params)
  File "C:\Python34\lib\site-packages\django\db\utils.py", line 98, in __exit__
    six.reraise(dj_exc_type, dj_exc_value, traceback)
  File "C:\Python34\lib\site-packages\django\utils\six.py", line 658, in reraise
    raise value.with_traceback(tb)
  File "C:\Python34\lib\site-packages\django\db\backends\utils.py", line 64, in execute
    return self.cursor.execute(sql, params)
  File "C:\Python34\lib\site-packages\django\db\backends\mysql\base.py", line 124, in execute
    return self.cursor.execute(query, args)
  File "C:\Python34\lib\site-packages\pymysql\cursors.py", line 158, in execute
    result = self._query(query)
  File "C:\Python34\lib\site-packages\pymysql\cursors.py", line 308, in _query
    conn.query(q)
  File "C:\Python34\lib\site-packages\pymysql\connections.py", line 820, in query
    self._affected_rows = self._read_query_result(unbuffered=unbuffered)
  File "C:\Python34\lib\site-packages\pymysql\connections.py", line 1002, in _read_query_result
    result.read()
  File "C:\Python34\lib\site-packages\pymysql\connections.py", line 1285, in read
    first_packet = self.connection._read_packet()
  File "C:\Python34\lib\site-packages\pymysql\connections.py", line 966, in _read_packet
    packet.check_error()
  File "C:\Python34\lib\site-packages\pymysql\connections.py", line 394, in check_error
    err.raise_mysql_exception(self._data)
  File "C:\Python34\lib\site-packages\pymysql\err.py", line 120, in raise_mysql_exception
    _check_mysql_exception(errinfo)
  File "C:\Python34\lib\site-packages\pymysql\err.py", line 115, in _check_mysql_exception
    raise InternalError(errno, errorvalue)
django.db.utils.InternalError: (1054, "Unknown column 'payment.dis_rate' in 'field list'")
2017-01-21 12:42:02,130 [Thread-81:14024] [django.request:170] [base:get_response] [WARNING]- Not Found: /js/jquery.min.map
2017-01-21 13:22:40,851 [Thread-25:2068] [django.request:170] [base:get_response] [WARNING]- Not Found: /js/jquery.min.map
2017-01-21 14:19:49,925 [Thread-12:9500] [django.request:170] [base:get_response] [WARNING]- Not Found: /js/jquery.min.map
2017-01-21 14:20:00,640 [Thread-15:11408] [django.request:170] [base:get_response] [WARNING]- Not Found: /js/jquery.min.map
2017-01-21 14:20:05,874 [Thread-17:6252] [django.request:170] [base:get_response] [WARNING]- Not Found: /js/jquery.min.map
2017-01-21 14:20:06,898 [Thread-18:14004] [django.request:170] [base:get_response] [WARNING]- Not Found: /kg/sellcard/fornt/nopay/ordinary/detail/favicon.ico
2017-01-21 16:00:55,074 [Thread-21:10392] [django.request:170] [base:get_response] [WARNING]- Not Found: /js/table-my..js
2017-01-21 16:10:02,590 [Thread-34:976] [django.request:170] [base:get_response] [WARNING]- Not Found: /js/table-my..js
2017-01-21 16:10:02,662 [Thread-41:2148] [django.request:170] [base:get_response] [WARNING]- Not Found: /js/jquery.min.map
2017-01-21 16:10:18,178 [Thread-51:11564] [django.request:170] [base:get_response] [WARNING]- Not Found: /js/jquery.min.map
2017-01-21 16:10:28,921 [Thread-53:13928] [django.request:170] [base:get_response] [WARNING]- Not Found: /js/jquery.min.map
2017-01-21 16:12:58,168 [Thread-66:11168] [django.request:170] [base:get_response] [WARNING]- Not Found: /js/table-my..js
2017-01-21 16:13:15,958 [Thread-86:13120] [django.request:170] [base:get_response] [WARNING]- Not Found: /kg/sellcard/index/favicon.ico
2017-01-21 16:13:18,872 [Thread-87:11376] [django.request:170] [base:get_response] [WARNING]- Not Found: /js/jquery.min.map
2017-01-21 16:13:23,812 [Thread-106:196] [django.request:170] [base:get_response] [WARNING]- Not Found: /js/jquery.min.map
2017-01-21 16:13:35,614 [Thread-125:8156] [django.request:170] [base:get_response] [WARNING]- Not Found: /js/jquery.min.map
2017-01-21 16:13:44,837 [Thread-143:14072] [django.request:170] [base:get_response] [WARNING]- Not Found: /js/jquery.min.map
2017-01-21 16:13:55,771 [Thread-166:13564] [django.request:170] [base:get_response] [WARNING]- Not Found: /js/jquery.min.map
2017-01-21 16:14:00,110 [Thread-184:12488] [django.request:170] [base:get_response] [WARNING]- Not Found: /js/jquery.min.map
2017-01-21 16:14:04,283 [Thread-202:13204] [django.request:170] [base:get_response] [WARNING]- Not Found: /js/jquery.min.map
2017-01-21 16:14:05,528 [Thread-232:13836] [django.request:170] [base:get_response] [WARNING]- Not Found: /js/jquery.min.map
2017-01-21 16:14:06,024 [Thread-253:9412] [django.request:170] [base:get_response] [WARNING]- Not Found: /js/jquery.min.map
2017-01-21 16:14:18,240 [Thread-254:4660] [django.request:170] [base:get_response] [WARNING]- Not Found: /js/jquery.min.map
2017-01-21 16:14:26,955 [Thread-273:8336] [django.request:170] [base:get_response] [WARNING]- Not Found: /js/jquery.min.map
2017-01-21 16:14:30,028 [Thread-292:10672] [django.request:170] [base:get_response] [WARNING]- Not Found: /js/jquery.min.map
2017-01-21 16:14:33,031 [Thread-295:13700] [django.request:170] [base:get_response] [WARNING]- Not Found: /js/jquery.min.map
2017-01-21 16:14:33,115 [Thread-296:6112] [django.request:170] [base:get_response] [WARNING]- Not Found: /kg/sellcard/fornt/cardsale/favicon.ico
2017-01-21 16:15:04,909 [Thread-313:8972] [django.request:170] [base:get_response] [WARNING]- Not Found: /js/jquery.min.map
2017-01-21 16:15:10,103 [Thread-334:14024] [django.request:170] [base:get_response] [WARNING]- Not Found: /js/jquery.min.map
2017-01-21 16:18:34,915 [Thread-366:7484] [django.request:170] [base:get_response] [WARNING]- Not Found: /js/jquery.min.map
2017-01-21 16:19:00,449 [Thread-370:7244] [django.request:170] [base:get_response] [WARNING]- Not Found: /js/jquery.min.map
2017-01-21 16:23:40,458 [Thread-399:616] [django.request:170] [base:get_response] [WARNING]- Not Found: /js/jquery.min.map
2017-01-21 16:24:28,816 [Thread-14:12804] [django.request:170] [base:get_response] [WARNING]- Not Found: /js/table-my..js
